---
layout: post
title: lua 异常与错误
date: 2017-03-15 17:31:15
categories: 编程语言 lua
tags: lua  
excerpt: lua error and assert
---

### assert 

Lua 提供了专门的内置函数 assert 来完成错误的检测的功能。

```lua
print "enter a number:"
n = assert(io.read("*number"), "invalid input")
```

assert 首先检查第一个参数是否返回错误，如果不返回错误 assert 简单的返回，否则assert 以第二个参数抛出错误信息。第二个参数是可选的。

当函数遇到异常有两个基本的动作：返回错误代码或者抛出错误。这两种方式选择
哪一种没有固定的规则，但有一般的原则：容易避免的异常应该抛出错误否则返回错误
代码。

### 异常和错误处理

在 Lua 中需要处理错误，需要使用 pcall 函数封装你的代码。
用法如下：

```lua
if pcall(foo) then
	-- no errors while running `foo'
...
else
-- `foo' raised an error: take appropriate actions
...
end

```
foo 为检测的函数。

用做匿名函数则是：

```lua

if pcall(function () ... end) then ...
else ...

```
pcall 在保护模式下调用他的第一个参数并运行，因此可以捕获所有的异常和错误。
如果没有异常和错误，pcall 返回 true 和调用返回的任何值；否则返回 nil 加错误信息。

#### 错误信息和回跟踪（Tracebacks）

通常在错误发生时，希望落得更多的调试信息，而不只是发生错误的位置。但pcall返回时，它已经销毁了调用桟的部分内容。Lua提供了xpcall函数，xpcall接收第二个参数——一个错误处理函数，当错误发生时，Lua会在调用桟展看（unwind）前调用错误处理函数，于是就可以在这个函数中使用debug库来获取关于错误的额外信息了。

debug库提供了两个通用的错误处理函数:
- debug.debug：提供一个Lua提示符，让用户来价差错误的原因
- debug.traceback：根据调用桟来构建一个扩展的错误消息。

```lua
xpcall(function(i) print(i) error('error..') end, function() print(debug.traceback()) end, 33)
```




